Workbook

Sheet Promedio salarial
B2: Pega tus semanas aquí 👇 | E2: No Modificar | L2: Salario promedio de las últimas 250 semanas - actualidad
B3: TIPO DE MOVIMIENTO | C3: FECHA DE INICIO | D3: SALARIO REGISTRADO | E3: FECHA DE TÉRMINO | L3: Nombre 👉 | M3: =Inicio!E3 -> #REF!
B4: MODIFICACION DE SALARIO | C4: 46023 | D4: 330.57 | E4: =IF(B4<>"BAJA",TODAY(),"") -> 46106 | G4: =IFERROR(__xludf.DUMMYFUNCTION("filter(B4:E1001,B4:B1001<>"""",B4:B1001<>""BAJA"")"),"MODIFICACION DE SALARIO") -> MODIFICACION DE SALARIO | H4: =IFERROR(__xludf.DUMMYFUNCTION("""COMPUTED_VALUE"""),46023.0) -> 46023 | I4: =IFERROR(__xludf.DUMMYFUNCTION("""COMPUTED_VALUE"""),330.57) -> 330.57 | J4: =IFERROR(__xludf.DUMMYFUNCTION("""COMPUTED_VALUE"""),46106.0) -> 46106 | L4: Total de semanas cotizadas | Q4: =Inicio!E7 -> #REF! | R4: =Q4+Inicio!E8 -> #REF!
B5: MODIFICACION DE SALARIO | C5: 45658 | D5: 292.54 | E5: =C4 -> 46023 | G5: =IFERROR(__xludf.DUMMYFUNCTION("""COMPUTED_VALUE"""),"MODIFICACION DE SALARIO") -> MODIFICACION DE SALARIO | H5: =IFERROR(__xludf.DUMMYFUNCTION("""COMPUTED_VALUE"""),45658.0) -> 45658 | I5: =IFERROR(__xludf.DUMMYFUNCTION("""COMPUTED_VALUE"""),292.54) -> 292.54 | J5: =IFERROR(__xludf.DUMMYFUNCTION("""COMPUTED_VALUE"""),46023.0) -> 46023 | L5: # de semanas a promediar | Q5: 250
B6: MODIFICACION DE SALARIO | C6: 45292 | D6: 261.2 | E6: =C5 -> 45658 | G6: =IFERROR(__xludf.DUMMYFUNCTION("""COMPUTED_VALUE"""),"MODIFICACION DE SALARIO") -> MODIFICACION DE SALARIO | H6: =IFERROR(__xludf.DUMMYFUNCTION("""COMPUTED_VALUE"""),45292.0) -> 45292 | I6: =IFERROR(__xludf.DUMMYFUNCTION("""COMPUTED_VALUE"""),261.2) -> 261.2 | J6: =IFERROR(__xludf.DUMMYFUNCTION("""COMPUTED_VALUE"""),45658.0) -> 45658 | L6: Salario de las semanas que se están promediando | Q6: =SUM(Q8:Q151)/250 -> 237.19755 | R6: =Q6*30.4 -> 7210.8055
B7: MODIFICACION DE SALARIO | C7: 44927 | D7: 217.67 | E7: =C6 -> 45292 | G7: =IFERROR(__xludf.DUMMYFUNCTION("""COMPUTED_VALUE"""),"MODIFICACION DE SALARIO") -> MODIFICACION DE SALARIO | H7: =IFERROR(__xludf.DUMMYFUNCTION("""COMPUTED_VALUE"""),44927.0) -> 44927 | I7: =IFERROR(__xludf.DUMMYFUNCTION("""COMPUTED_VALUE"""),217.67) -> 217.67 | J7: =IFERROR(__xludf.DUMMYFUNCTION("""COMPUTED_VALUE"""),45292.0) -> 45292 | L7: FECHA DE INICIO | M7: FECHA DE TÉRMINO | N7: SALARIO REGISTRADO | O7: SEMANAS COTIZADAS TOTALES | P7: SEMANAS COTIZADAS | Q7: RESULTADO
B8: REINGRESO | C8: 43435 | D8: 184.71 | E8: =C7 -> 44927 | G8: =IFERROR(__xludf.DUMMYFUNCTION("""COMPUTED_VALUE"""),"REINGRESO") -> REINGRESO | H8: =IFERROR(__xludf.DUMMYFUNCTION("""COMPUTED_VALUE"""),43435.0) -> 43435 | I8: =IFERROR(__xludf.DUMMYFUNCTION("""COMPUTED_VALUE"""),184.71) -> 184.71 | J8: =IFERROR(__xludf.DUMMYFUNCTION("""COMPUTED_VALUE"""),44927.0) -> 44927 | L8: =H4 -> 46023 | M8: =J4 -> 46106 | N8: =I4 -> 330.57 | O8: =DATEDIF(H4-1,J4,"d")/7 -> 12 | P8: =IF((M8-(L8-1))/7>250,250,(M8-(L8-1))/7) -> 12 | Q8: =IF(P8>0,P8*N8,0) -> 3966.84
B9: BAJA | C9: 37642 | D9: 263.02 | E9: =C8 -> 43435 | G9: =IFERROR(__xludf.DUMMYFUNCTION("""COMPUTED_VALUE"""),"MODIFICACION DE SALARIO") -> MODIFICACION DE SALARIO | H9: =IFERROR(__xludf.DUMMYFUNCTION("""COMPUTED_VALUE"""),37155.0) -> 37155 | I9: =IFERROR(__xludf.DUMMYFUNCTION("""COMPUTED_VALUE"""),263.02) -> 263.02 | J9: =IFERROR(__xludf.DUMMYFUNCTION("""COMPUTED_VALUE"""),37642.0) -> 37642 | L9: =H5 -> 45658 | M9: =J5 -> 46023 | N9: =I5 -> 292.54 | O9: =IF(H5="",0,DATEDIF(H5-1,J5,"d")/7) -> 52.285714 | P9: =IF((M9-(L9-1))/7+SUM($P$8:P8)>250,(250-SUM($P$8:P8)),(M9-(L9-1))/7) -> 52.285714 | Q9: =IF(P9>0,P9*N9,0) -> 15295.663
B10: MODIFICACION DE SALARIO | C10: 37155 | D10: 263.02 | E10: =C9 -> 37642 | G10: =IFERROR(__xludf.DUMMYFUNCTION("""COMPUTED_VALUE"""),"MODIFICACION DE SALARIO") -> MODIFICACION DE SALARIO | H10: =IFERROR(__xludf.DUMMYFUNCTION("""COMPUTED_VALUE"""),37005.0) -> 37005 | I10: =IFERROR(__xludf.DUMMYFUNCTION("""COMPUTED_VALUE"""),262.68) -> 262.68 | J10: =IFERROR(__xludf.DUMMYFUNCTION("""COMPUTED_VALUE"""),37155.0) -> 37155 | L10: =H6 -> 45292 | M10: =J6 -> 45658 | N10: =I6 -> 261.2 | O10: =IF(H6="",0,DATEDIF(H6-1,J6,"d")/7) -> 52.428571 | P10: =IF((M10-(L10-1))/7+SUM($P$8:P9)>250,(250-SUM($P$8:P9)),(M10-(L10-1))/7) -> 52.428571 | Q10: =IF(P10>0,P10*N10,0) -> 13694.343
B11: MODIFICACION DE SALARIO | C11: 37005 | D11: 262.68 | E11: =C10 -> 37155 | G11: =IFERROR(__xludf.DUMMYFUNCTION("""COMPUTED_VALUE"""),"MODIFICACION DE SALARIO") -> MODIFICACION DE SALARIO | H11: =IFERROR(__xludf.DUMMYFUNCTION("""COMPUTED_VALUE"""),36943.0) -> 36943 | I11: =IFERROR(__xludf.DUMMYFUNCTION("""COMPUTED_VALUE"""),261.3) -> 261.3 | J11: =IFERROR(__xludf.DUMMYFUNCTION("""COMPUTED_VALUE"""),37005.0) -> 37005 | L11: =H7 -> 44927 | M11: =J7 -> 45292 | N11: =I7 -> 217.67 | O11: =IF(H7="",0,DATEDIF(H7-1,J7,"d")/7) -> 52.285714 | P11: =IF((M11-(L11-1))/7+SUM($P$8:P10)>250,(250-SUM($P$8:P10)),(M11-(L11-1))/7) -> 52.285714 | Q11: =IF(P11>0,P11*N11,0) -> 11381.031
B12: MODIFICACION DE SALARIO | C12: 36943 | D12: 261.3 | E12: =C11 -> 37005 | G12: =IFERROR(__xludf.DUMMYFUNCTION("""COMPUTED_VALUE"""),"MODIFICACION DE SALARIO") -> MODIFICACION DE SALARIO | H12: =IFERROR(__xludf.DUMMYFUNCTION("""COMPUTED_VALUE"""),36745.0) -> 36745 | I12: =IFERROR(__xludf.DUMMYFUNCTION("""COMPUTED_VALUE"""),230.0) -> 230 | J12: =IFERROR(__xludf.DUMMYFUNCTION("""COMPUTED_VALUE"""),36943.0) -> 36943 | L12: =H8 -> 43435 | M12: =J8 -> 44927 | N12: =I8 -> 184.71 | O12: =IF(H8="",0,DATEDIF(H8-1,J8,"d")/7) -> 213.28571 | P12: =IF((M12-(L12-1))/7+SUM($P$8:P11)>250,(250-SUM($P$8:P11)),(M12-(L12-1))/7) -> 81 | Q12: =IF(P12>0,P12*N12,0) -> 14961.51
B13: MODIFICACION DE SALARIO | C13: 36745 | D13: 230 | E13: =C12 -> 36943 | G13: =IFERROR(__xludf.DUMMYFUNCTION("""COMPUTED_VALUE"""),"MODIFICACION DE SALARIO") -> MODIFICACION DE SALARIO | H13: =IFERROR(__xludf.DUMMYFUNCTION("""COMPUTED_VALUE"""),35886.0) -> 35886 | I13: =IFERROR(__xludf.DUMMYFUNCTION("""COMPUTED_VALUE"""),156.78) -> 156.78 | J13: =IFERROR(__xludf.DUMMYFUNCTION("""COMPUTED_VALUE"""),36745.0) -> 36745 | L13: =H9 -> 37155 | M13: =J9 -> 37642 | N13: =I9 -> 263.02 | O13: =IF(H9="",0,DATEDIF(H9-1,J9,"d")/7) -> 69.714286 | P13: =IF((M13-(L13-1))/7+SUM($P$8:P12)>250,(250-SUM($P$8:P12)),(M13-(L13-1))/7) -> 0 | Q13: =IF(P13>0,P13*N13,0) -> 0
B14: MODIFICACION DE SALARIO | C14: 35886 | D14: 156.78 | E14: =C13 -> 36745 | G14: =IFERROR(__xludf.DUMMYFUNCTION("""COMPUTED_VALUE"""),"MODIFICACION DE SALARIO") -> MODIFICACION DE SALARIO | H14: =IFERROR(__xludf.DUMMYFUNCTION("""COMPUTED_VALUE"""),35400.0) -> 35400 | I14: =IFERROR(__xludf.DUMMYFUNCTION("""COMPUTED_VALUE"""),104.52) -> 104.52 | J14: =IFERROR(__xludf.DUMMYFUNCTION("""COMPUTED_VALUE"""),35886.0) -> 35886 | L14: =H10 -> 37005 | M14: =J10 -> 37155 | N14: =I10 -> 262.68 | O14: =IF(H10="",0,DATEDIF(H10-1,J10,"d")/7) -> 21.571429 | P14: =IF((M14-(L14-1))/7+SUM($P$8:P13)>250,(250-SUM($P$8:P13)),(M14-(L14-1))/7) -> 0 | Q14: =IF(P14>0,P14*N14,0) -> 0
B15: MODIFICACION DE SALARIO | C15: 35400 | D15: 104.52 | E15: =C14 -> 35886 | G15: =IFERROR(__xludf.DUMMYFUNCTION("""COMPUTED_VALUE"""),"REINGRESO") -> REINGRESO | H15: =IFERROR(__xludf.DUMMYFUNCTION("""COMPUTED_VALUE"""),34912.0) -> 34912 | I15: =IFERROR(__xludf.DUMMYFUNCTION("""COMPUTED_VALUE"""),70.0) -> 70 | J15: =IFERROR(__xludf.DUMMYFUNCTION("""COMPUTED_VALUE"""),35400.0) -> 35400 | L15: =H11 -> 36943 | M15: =J11 -> 37005 | N15: =I11 -> 261.3 | O15: =IF(H11="",0,DATEDIF(H11-1,J11,"d")/7) -> 9 | P15: =IF((M15-(L15-1))/7+SUM($P$8:P14)>250,(250-SUM($P$8:P14)),(M15-(L15-1))/7) -> 0 | Q15: =IF(P15>0,P15*N15,0) -> 0
B16: REINGRESO | C16: 34912 | D16: 70 | E16: =C15 -> 35400 | G16: =IFERROR(__xludf.DUMMYFUNCTION("""COMPUTED_VALUE"""),"ALTA") -> ALTA | H16: =IFERROR(__xludf.DUMMYFUNCTION("""COMPUTED_VALUE"""),34127.0) -> 34127 | I16: =IFERROR(__xludf.DUMMYFUNCTION("""COMPUTED_VALUE"""),30.57) -> 30.57 | J16: =IFERROR(__xludf.DUMMYFUNCTION("""COMPUTED_VALUE"""),34145.0) -> 34145 | L16: =H12 -> 36745 | M16: =J12 -> 36943 | N16: =I12 -> 230 | O16: =IF(H12="",0,DATEDIF(H12-1,J12,"d")/7) -> 28.428571 | P16: =IF((M16-(L16-1))/7+SUM($P$8:P15)>250,(250-SUM($P$8:P15)),(M16-(L16-1))/7) -> 0 | Q16: =IF(P16>0,P16*N16,0) -> 0
B17: BAJA | C17: 34145 | D17: 30.57 | E17: =C16 -> 34912 | L17: =H13 -> 35886 | M17: =J13 -> 36745 | N17: =I13 -> 156.78 | O17: =IF(H13="",0,DATEDIF(H13-1,J13,"d")/7) -> 122.85714 | P17: =IF((M17-(L17-1))/7+SUM($P$8:P16)>250,(250-SUM($P$8:P16)),(M17-(L17-1))/7) -> 0 | Q17: =IF(P17>0,P17*N17,0) -> 0
B18: ALTA | C18: 34127 | D18: 30.57 | E18: =C17 -> 34145 | L18: =H14 -> 35400 | M18: =J14 -> 35886 | N18: =I14 -> 104.52 | O18: =IF(H14="",0,DATEDIF(H14-1,J14,"d")/7) -> 69.571429 | P18: =IF((M18-(L18-1))/7+SUM($P$8:P17)>250,(250-SUM($P$8:P17)),(M18-(L18-1))/7) -> 0 | Q18: =IF(P18>0,P18*N18,0) -> 0
E19: =C18 -> 34127 | L19: =H15 -> 34912 | M19: =J15 -> 35400 | N19: =I15 -> 70 | O19: =IF(H15="",0,DATEDIF(H15-1,J15,"d")/7) -> 69.857143 | P19: =IF((M19-(L19-1))/7+SUM($P$8:P18)>250,(250-SUM($P$8:P18)),(M19-(L19-1))/7) -> 0 | Q19: =IF(P19>0,P19*N19,0) -> 0
E20: =C19 | L20: =H16 -> 34127 | M20: =J16 -> 34145 | N20: =I16 -> 30.57 | O20: =IF(H16="",0,DATEDIF(H16-1,J16,"d")/7) -> 2.7142857 | P20: =IF((M20-(L20-1))/7+SUM($P$8:P19)>250,(250-SUM($P$8:P19)),(M20-(L20-1))/7) -> 0 | Q20: =IF(P20>0,P20*N20,0) -> 0
E21: =C20 | L21: =H17 | M21: =J17 | N21: =I17 | O21: =IF(H17="",0,DATEDIF(H17-1,J17,"d")/7) -> 0 | P21: =IF((M21-(L21-1))/7+SUM($P$8:P20)>250,(250-SUM($P$8:P20)),(M21-(L21-1))/7) -> 0 | Q21: =IF(P21>0,P21*N21,0) -> 0
E22: =C21 | L22: =H18 | M22: =J18 | N22: =I18 | O22: =IF(H18="",0,DATEDIF(H18-1,J18,"d")/7) -> 0 | P22: =IF((M22-(L22-1))/7+SUM($P$8:P21)>250,(250-SUM($P$8:P21)),(M22-(L22-1))/7) -> 0 | Q22: =IF(P22>0,P22*N22,0) -> 0
E23: =C22 | L23: =H19 | M23: =J19 | N23: =I19 | O23: =IF(H19="",0,DATEDIF(H19-1,J19,"d")/7) -> 0 | P23: =IF((M23-(L23-1))/7+SUM($P$8:P22)>250,(250-SUM($P$8:P22)),(M23-(L23-1))/7) -> 0 | Q23: =IF(P23>0,P23*N23,0) -> 0
E24: =C23 | L24: =H20 | M24: =J20 | N24: =I20 | O24: =IF(H20="",0,DATEDIF(H20-1,J20,"d")/7) -> 0 | P24: =IF((M24-(L24-1))/7+SUM($P$8:P23)>250,(250-SUM($P$8:P23)),(M24-(L24-1))/7) -> 0 | Q24: =IF(P24>0,P24*N24,0) -> 0
E25: =C24 | L25: =H21 | M25: =J21 | N25: =I21 | O25: =IF(H21="",0,DATEDIF(H21-1,J21,"d")/7) -> 0 | P25: =IF((M25-(L25-1))/7+SUM($P$8:P24)>250,(250-SUM($P$8:P24)),(M25-(L25-1))/7) -> 0 | Q25: =IF(P25>0,P25*N25,0) -> 0
E26: =C25 | L26: =H22 | M26: =J22 | N26: =I22 | O26: =IF(H22="",0,DATEDIF(H22-1,J22,"d")/7) -> 0 | P26: =IF((M26-(L26-1))/7+SUM($P$8:P25)>250,(250-SUM($P$8:P25)),(M26-(L26-1))/7) -> 0 | Q26: =IF(P26>0,P26*N26,0) -> 0
E27: =C26 | L27: =H23 | M27: =J23 | N27: =I23 | O27: =IF(H23="",0,DATEDIF(H23-1,J23,"d")/7) -> 0 | P27: =IF((M27-(L27-1))/7+SUM($P$8:P26)>250,(250-SUM($P$8:P26)),(M27-(L27-1))/7) -> 0 | Q27: =IF(P27>0,P27*N27,0) -> 0
E28: =C27 | L28: =H24 | M28: =J24 | N28: =I24 | O28: =IF(H24="",0,DATEDIF(H24-1,J24,"d")/7) -> 0 | P28: =IF((M28-(L28-1))/7+SUM($P$8:P27)>250,(250-SUM($P$8:P27)),(M28-(L28-1))/7) -> 0 | Q28: =IF(P28>0,P28*N28,0) -> 0
E29: =C28 | L29: =H25 | M29: =J25 | N29: =I25 | O29: =IF(H25="",0,DATEDIF(H25-1,J25,"d")/7) -> 0 | P29: =IF((M29-(L29-1))/7+SUM($P$8:P28)>250,(250-SUM($P$8:P28)),(M29-(L29-1))/7) -> 0 | Q29: =IF(P29>0,P29*N29,0) -> 0
E30: =C29 | L30: =H26 | M30: =J26 | N30: =I26 | O30: =IF(H26="",0,DATEDIF(H26-1,J26,"d")/7) -> 0 | P30: =IF((M30-(L30-1))/7+SUM($P$8:P29)>250,(250-SUM($P$8:P29)),(M30-(L30-1))/7) -> 0 | Q30: =IF(P30>0,P30*N30,0) -> 0
... E320: =C319 | L320: =H316 | M320: =J316 | N320: =I316 | O320: =IF(H316="",0,DATEDIF(H316-1,J316,"d")/7) -> 0 | P320: =IF((M320-(L320-1))/7+SUM($P$8:P319)>250,(250-SUM($P$8:P319)),(M320-(L320-1))/7) -> 0 | Q320: =IF(P320>0,P320*N320,0) -> 0
E321: =C320
E322: =C321
E323: =C322
E324: =C323
E325: =C324
E326: =C325
E327: =C326
E328: =C327
E329: =C328
E330: =C329
...

Sheet SaldoAfore
B2: Saldo Actual Cuentas AFORE a Regresar | E2: =CalculoAfore!F269+CalculoAfore!H269+CalculoAfore!O269+CalculoAfore!Q269 -> 176636.32
B4: CAUSAS POR LAS QUE EL SALDO PODRIA SER MENOR AL CALCULADO
B5: Retiros Parciales por Desempleo
B6: Retiro Parcial por Matrimonio
B7: Usó Credito Infonavit

Sheet SalarioPromedio
B4: FECHA ALTA | C4: FECHA BAJA | D4: SALARIO DIARIO | E4: DÍAS | F4: SEMANAS
B5: =IF('Promedio salarial'!L8="","",'Promedio salarial'!L8) -> 46023 | C5: =IF('Promedio salarial'!M8="","",'Promedio salarial'!M8) -> 46106 | D5: =IF('Promedio salarial'!N8="","",'Promedio salarial'!N8) -> 330.57 | E5: =IF(B5="",0,(IFERROR(IF(OR(ISBLANK(B5),ISBLANK(C5)),0,IF(((C5-B5+1)+H4)>1750,1750-H4,C5-B5+1)),0))) -> 84 | F5: =+E5/7 -> 12 | G5: =F5 -> 12 | H5: =+E5 -> 84 | I5: =IF(D5="",0,(D5*E5)) -> 27767.88
B6: =IF('Promedio salarial'!L9="","",'Promedio salarial'!L9) -> 45658 | C6: =IF('Promedio salarial'!M9="","",'Promedio salarial'!M9) -> 46023 | D6: =IF('Promedio salarial'!N9="","",'Promedio salarial'!N9) -> 292.54 | E6: =IF(B6="",0,(IFERROR(IF(OR(ISBLANK(B6),ISBLANK(C6)),0,IF(((C6-B6+1)+H5)>1750,1750-H5,C6-B6+1)),0))) -> 366 | F6: =+E6/7 -> 52.285714 | G6: =F6 -> 52.285714 | H6: =+E6 -> 366 | I6: =IF(D6="",0,(D6*E6)) -> 107069.64
B7: =IF('Promedio salarial'!L10="","",'Promedio salarial'!L10) -> 45292 | C7: =IF('Promedio salarial'!M10="","",'Promedio salarial'!M10) -> 45658 | D7: =IF('Promedio salarial'!N10="","",'Promedio salarial'!N10) -> 261.2 | E7: =IF(B7="",0,(IFERROR(IF(OR(ISBLANK(B7),ISBLANK(C7)),0,IF(((C7-B7+1)+H6)>1750,1750-H6,C7-B7+1)),0))) -> 367 | F7: =+E7/7 -> 52.428571 | G7: =F7 -> 52.428571 | H7: =+E7 -> 367 | I7: =IF(D7="",0,(D7*E7)) -> 95860.4
B8: =IF('Promedio salarial'!L11="","",'Promedio salarial'!L11) -> 44927 | C8: =IF('Promedio salarial'!M11="","",'Promedio salarial'!M11) -> 45292 | D8: =IF('Promedio salarial'!N11="","",'Promedio salarial'!N11) -> 217.67 | E8: =IF(B8="",0,(IFERROR(IF(OR(ISBLANK(B8),ISBLANK(C8)),0,IF(((C8-B8+1)+H7)>1750,1750-H7,C8-B8+1)),0))) -> 366 | F8: =+E8/7 -> 52.285714 | G8: =F8 -> 52.285714 | H8: =+E8 -> 366 | I8: =IF(D8="",0,(D8*E8)) -> 79667.22
B9: =IF('Promedio salarial'!L12="","",'Promedio salarial'!L12) -> 43435 | C9: =IF('Promedio salarial'!M12="","",'Promedio salarial'!M12) -> 44927 | D9: =IF('Promedio salarial'!N12="","",'Promedio salarial'!N12) -> 184.71 | E9: =IF(B9="",0,(IFERROR(IF(OR(ISBLANK(B9),ISBLANK(C9)),0,IF(((C9-B9+1)+H8)>1750,1750-H8,C9-B9+1)),0))) -> 1384 | F9: =+E9/7 -> 197.71429 | G9: =F9 -> 197.71429 | H9: =+E9 -> 1384 | I9: =IF(D9="",0,(D9*E9)) -> 255638.64
B10: =IF('Promedio salarial'!L13="","",'Promedio salarial'!L13) -> 37155 | C10: =IF('Promedio salarial'!M13="","",'Promedio salarial'!M13) -> 37642 | D10: =IF('Promedio salarial'!N13="","",'Promedio salarial'!N13) -> 263.02 | E10: =IF(B10="",0,(IFERROR(IF(OR(ISBLANK(B10),ISBLANK(C10)),0,IF(((C10-B10+1)+H9)>1750,1750-H9,C10-B10+1)),0))) -> 366 | F10: =+E10/7 -> 52.285714 | G10: =F10 -> 52.285714 | H10: =+E10 -> 366 | I10: =IF(D10="",0,(D10*E10)) -> 96265.32
B11: =IF('Promedio salarial'!L14="","",'Promedio salarial'!L14) -> 37005 | C11: =IF('Promedio salarial'!M14="","",'Promedio salarial'!M14) -> 37155 | D11: =IF('Promedio salarial'!N14="","",'Promedio salarial'!N14) -> 262.68 | E11: =IF(B11="",0,(IFERROR(IF(OR(ISBLANK(B11),ISBLANK(C11)),0,IF(((C11-B11+1)+H10)>1750,1750-H10,C11-B11+1)),0))) -> 151 | F11: =+E11/7 -> 21.571429 | G11: =F11 -> 21.571429 | H11: =+E11 -> 151 | I11: =IF(D11="",0,(D11*E11)) -> 39664.68
B12: =IF('Promedio salarial'!L15="","",'Promedio salarial'!L15) -> 36943 | C12: =IF('Promedio salarial'!M15="","",'Promedio salarial'!M15) -> 37005 | D12: =IF('Promedio salarial'!N15="","",'Promedio salarial'!N15) -> 261.3 | E12: =IF(B12="",0,(IFERROR(IF(OR(ISBLANK(B12),ISBLANK(C12)),0,IF(((C12-B12+1)+H11)>1750,1750-H11,C12-B12+1)),0))) -> 63 | F12: =+E12/7 -> 9 | G12: =F12 -> 9 | H12: =+E12 -> 63 | I12: =IF(D12="",0,(D12*E12)) -> 16461.9
B13: =IF('Promedio salarial'!L16="","",'Promedio salarial'!L16) -> 36745 | C13: =IF('Promedio salarial'!M16="","",'Promedio salarial'!M16) -> 36943 | D13: =IF('Promedio salarial'!N16="","",'Promedio salarial'!N16) -> 230 | E13: =IF(B13="",0,(IFERROR(IF(OR(ISBLANK(B13),ISBLANK(C13)),0,IF(((C13-B13+1)+H12)>1750,1750-H12,C13-B13+1)),0))) -> 199 | F13: =+E13/7 -> 28.428571 | G13: =F13 -> 28.428571 | H13: =+E13 -> 199 | I13: =IF(D13="",0,(D13*E13)) -> 45770
B14: =IF('Promedio salarial'!L17="","",'Promedio salarial'!L17) -> 35886 | C14: =IF('Promedio salarial'!M17="","",'Promedio salarial'!M17) -> 36745 | D14: =IF('Promedio salarial'!N17="","",'Promedio salarial'!N17) -> 156.78 | E14: =IF(B14="",0,(IFERROR(IF(OR(ISBLANK(B14),ISBLANK(C14)),0,IF(((C14-B14+1)+H13)>1750,1750-H13,C14-B14+1)),0))) -> 860 | F14: =+E14/7 -> 122.85714 | G14: =F14 -> 122.85714 | H14: =+E14 -> 860 | I14: =IF(D14="",0,(D14*E14)) -> 134830.8
B15: =IF('Promedio salarial'!L18="","",'Promedio salarial'!L18) -> 35400 | C15: =IF('Promedio salarial'!M18="","",'Promedio salarial'!M18) -> 35886 | D15: =IF('Promedio salarial'!N18="","",'Promedio salarial'!N18) -> 104.52 | E15: =IF(B15="",0,(IFERROR(IF(OR(ISBLANK(B15),ISBLANK(C15)),0,IF(((C15-B15+1)+H14)>1750,1750-H14,C15-B15+1)),0))) -> 487 | F15: =+E15/7 -> 69.571429 | G15: =F15 -> 69.571429 | H15: =+E15 -> 487 | I15: =IF(D15="",0,(D15*E15)) -> 50901.24
B16: =IF('Promedio salarial'!L19="","",'Promedio salarial'!L19) -> 34912 | C16: =IF('Promedio salarial'!M19="","",'Promedio salarial'!M19) -> 35400 | D16: =IF('Promedio salarial'!N19="","",'Promedio salarial'!N19) -> 70 | E16: =IF(B16="",0,(IFERROR(IF(OR(ISBLANK(B16),ISBLANK(C16)),0,IF(((C16-B16+1)+H15)>1750,1750-H15,C16-B16+1)),0))) -> 489 | F16: =+E16/7 -> 69.857143 | G16: =F16 -> 69.857143 | H16: =+E16 -> 489 | I16: =IF(D16="",0,(D16*E16)) -> 34230
... B265: =IF('Promedio salarial'!L268="","",'Promedio salarial'!L268) | C265: =IF('Promedio salarial'!M268="","",'Promedio salarial'!M268) | D265: =IF('Promedio salarial'!N268="","",'Promedio salarial'!N268) | E265: =IF(B265="",0,(IFERROR(IF(OR(ISBLANK(B265),ISBLANK(C265)),0,IF(((C265-B265+1)+H264)>1750,1750-H264,C265-B265+1)),0))) -> 0 | F265: =+E265/7 -> 0 | G265: =F265 -> 0 | H265: =+E265 -> 0 | I265: =IF(D265="",0,(D265*E265)) -> 0
D266: Suma | E266: 0 | F266: 0 | I266: $ -
D267: S. D. Promedio | I267: $ -

Sheet CalculoAfore
B3: No considera Comisiones de AFORE | G3: Retiro | I3: RCV
B4: salario diario | C4: Dias | E4: SAR 92 | F4: Rendimientos | G4: SAR 97 | H4: Rendimientos | I4: Aportacion Trabajador | J4: Rendimientos | K4: Aportacion Patronal | L4: Rendimientos | M4: Cuota Social | N4: Vivienda 92 | O4: Rendimientos | P4: Vivienda 97 | Q4: Rendimientos
A5: =IFERROR(YEAR(SalarioPromedio!B5),"") -> 2026 | B5: =SalarioPromedio!D5 -> 330.57 | C5: =IF(SalarioPromedio!B5="",0,SalarioPromedio!C5-SalarioPromedio!B5+1) -> 84 | D5: =IF(SalarioPromedio!B5="",0,C5*B5) -> 27767.88 | E5: =IFERROR(IF(VALUE(A5)<1998,D5*0.02,0),0) -> 0 | F5: =IFERROR(IF(VALUE($A5)>1996,(2026-$A5)*0.1048*E5,0),0) -> 0 | G5: =IFERROR(IF(VALUE(A5)>1997,D5*0.02,0),0) -> 555.3576 | H5: =IFERROR(IF(VALUE($A5)>1996,(2026-$A5)*0.1048*G5,0),0) -> 0 | I5: =IFERROR(IF(VALUE(A5)>1997,D5*0.01125,0),0) -> 312.38865 | J5: =IFERROR(IF(VALUE($A5)>1996,(2026-$A5)*0.1048*I5,0),0) -> 0 | K5: =IFERROR(IF(VALUE(A5)<1997,0,IF(AND(VALUE(A5)>1997),D5*0.0315,0)),0) -> 874.68822 | L5: =IFERROR(IF(VALUE($A5)>1996,(2026-$A5)*0.1048*K5,0),0) -> 0 | N5: =IFERROR(IF(VALUE(A5)<1998,D5*0.05,0),0) -> 0 | O5: =IFERROR((2026-$A5)*0.1048*N5,0) -> 0 | P5: =IFERROR(IF(VALUE(A5)>1997,D5*0.05,0),0) -> 1388.394 | Q5: =IFERROR((2026-$A5)*0.1048*P5,0) -> 0
A6: =IFERROR(YEAR(SalarioPromedio!B6),"") -> 2025 | B6: =SalarioPromedio!D6 -> 292.54 | C6: =IF(SalarioPromedio!B6="",0,SalarioPromedio!C6-SalarioPromedio!B6+1) -> 366 | D6: =IF(SalarioPromedio!B6="",0,C6*B6) -> 107069.64 | E6: =IFERROR(IF(VALUE(A6)<1998,D6*0.02,0),0) -> 0 | F6: =IFERROR(IF(VALUE($A6)>1996,(2026-$A6)*0.1048*E6,0),0) -> 0 | G6: =IFERROR(IF(VALUE(A6)>1997,D6*0.02,0),0) -> 2141.3928 | H6: =IFERROR(IF(VALUE($A6)>1996,(2026-$A6)*0.1048*G6,0),0) -> 224.41797 | I6: =IFERROR(IF(VALUE(A6)>1997,D6*0.01125,0),0) -> 1204.5334 | J6: =IFERROR(IF(VALUE($A6)>1996,(2026-$A6)*0.1048*I6,0),0) -> 126.23511 | K6: =IFERROR(IF(VALUE(A6)<1997,0,IF(AND(VALUE(A6)>1997),D6*0.0315,0)),0) -> 3372.6937 | L6: =IFERROR(IF(VALUE($A6)>1996,(2026-$A6)*0.1048*K6,0),0) -> 353.4583 | N6: =IFERROR(IF(VALUE(A6)<1998,D6*0.05,0),0) -> 0 | O6: =IFERROR((2026-$A6)*0.1048*N6,0) -> 0 | P6: =IFERROR(IF(VALUE(A6)>1997,D6*0.05,0),0) -> 5353.482 | Q6: =IFERROR((2026-$A6)*0.1048*P6,0) -> 561.04491
A7: =IFERROR(YEAR(SalarioPromedio!B7),"") -> 2024 | B7: =SalarioPromedio!D7 -> 261.2 | C7: =IF(SalarioPromedio!B7="",0,SalarioPromedio!C7-SalarioPromedio!B7+1) -> 367 | D7: =IF(SalarioPromedio!B7="",0,C7*B7) -> 95860.4 | E7: =IFERROR(IF(VALUE(A7)<1998,D7*0.02,0),0) -> 0 | F7: =IFERROR(IF(VALUE($A7)>1996,(2026-$A7)*0.1048*E7,0),0) -> 0 | G7: =IFERROR(IF(VALUE(A7)>1997,D7*0.02,0),0) -> 1917.208 | H7: =IFERROR(IF(VALUE($A7)>1996,(2026-$A7)*0.1048*G7,0),0) -> 401.8468 | I7: =IFERROR(IF(VALUE(A7)>1997,D7*0.01125,0),0) -> 1078.4295 | J7: =IFERROR(IF(VALUE($A7)>1996,(2026-$A7)*0.1048*I7,0),0) -> 226.03882 | K7: =IFERROR(IF(VALUE(A7)<1997,0,IF(AND(VALUE(A7)>1997),D7*0.0315,0)),0) -> 3019.6026 | L7: =IFERROR(IF(VALUE($A7)>1996,(2026-$A7)*0.1048*K7,0),0) -> 632.90871 | N7: =IFERROR(IF(VALUE(A7)<1998,D7*0.05,0),0) -> 0 | O7: =IFERROR((2026-$A7)*0.1048*N7,0) -> 0 | P7: =IFERROR(IF(VALUE(A7)>1997,D7*0.05,0),0) -> 4793.02 | Q7: =IFERROR((2026-$A7)*0.1048*P7,0) -> 1004.617
A8: =IFERROR(YEAR(SalarioPromedio!B8),"") -> 2023 | B8: =SalarioPromedio!D8 -> 217.67 | C8: =IF(SalarioPromedio!B8="",0,SalarioPromedio!C8-SalarioPromedio!B8+1) -> 366 | D8: =IF(SalarioPromedio!B8="",0,C8*B8) -> 79667.22 | E8: =IFERROR(IF(VALUE(A8)<1998,D8*0.02,0),0) -> 0 | F8: =IFERROR(IF(VALUE($A8)>1996,(2026-$A8)*0.1048*E8,0),0) -> 0 | G8: =IFERROR(IF(VALUE(A8)>1997,D8*0.02,0),0) -> 1593.3444 | H8: =IFERROR(IF(VALUE($A8)>1996,(2026-$A8)*0.1048*G8,0),0) -> 500.94748 | I8: =IFERROR(IF(VALUE(A8)>1997,D8*0.01125,0),0) -> 896.25622 | J8: =IFERROR(IF(VALUE($A8)>1996,(2026-$A8)*0.1048*I8,0),0) -> 281.78296 | K8: =IFERROR(IF(VALUE(A8)<1997,0,IF(AND(VALUE(A8)>1997),D8*0.0315,0)),0) -> 2509.5174 | L8: =IFERROR(IF(VALUE($A8)>1996,(2026-$A8)*0.1048*K8,0),0) -> 788.99228 | N8: =IFERROR(IF(VALUE(A8)<1998,D8*0.05,0),0) -> 0 | O8: =IFERROR((2026-$A8)*0.1048*N8,0) -> 0 | P8: =IFERROR(IF(VALUE(A8)>1997,D8*0.05,0),0) -> 3983.361 | Q8: =IFERROR((2026-$A8)*0.1048*P8,0) -> 1252.3687
A9: =IFERROR(YEAR(SalarioPromedio!B9),"") -> 2018 | B9: =SalarioPromedio!D9 -> 184.71 | C9: =IF(SalarioPromedio!B9="",0,SalarioPromedio!C9-SalarioPromedio!B9+1) -> 1493 | D9: =IF(SalarioPromedio!B9="",0,C9*B9) -> 275772.03 | E9: =IFERROR(IF(VALUE(A9)<1998,D9*0.02,0),0) -> 0 | F9: =IFERROR(IF(VALUE($A9)>1996,(2026-$A9)*0.1048*E9,0),0) -> 0 | G9: =IFERROR(IF(VALUE(A9)>1997,D9*0.02,0),0) -> 5515.4406 | H9: =IFERROR(IF(VALUE($A9)>1996,(2026-$A9)*0.1048*G9,0),0) -> 4624.1454 | I9: =IFERROR(IF(VALUE(A9)>1997,D9*0.01125,0),0) -> 3102.4353 | J9: =IFERROR(IF(VALUE($A9)>1996,(2026-$A9)*0.1048*I9,0),0) -> 2601.0818 | K9: =IFERROR(IF(VALUE(A9)<1997,0,IF(AND(VALUE(A9)>1997),D9*0.0315,0)),0) -> 8686.8189 | L9: =IFERROR(IF(VALUE($A9)>1996,(2026-$A9)*0.1048*K9,0),0) -> 7283.029 | N9: =IFERROR(IF(VALUE(A9)<1998,D9*0.05,0),0) -> 0 | O9: =IFERROR((2026-$A9)*0.1048*N9,0) -> 0 | P9: =IFERROR(IF(VALUE(A9)>1997,D9*0.05,0),0) -> 13788.602 | Q9: =IFERROR((2026-$A9)*0.1048*P9,0) -> 11560.363
A10: =IFERROR(YEAR(SalarioPromedio!B10),"") -> 2001 | B10: =SalarioPromedio!D10 -> 263.02 | C10: =IF(SalarioPromedio!B10="",0,SalarioPromedio!C10-SalarioPromedio!B10+1) -> 488 | D10: =IF(SalarioPromedio!B10="",0,C10*B10) -> 128353.76 | E10: =IFERROR(IF(VALUE(A10)<1998,D10*0.02,0),0) -> 0 | F10: =IFERROR(IF(VALUE($A10)>1996,(2026-$A10)*0.1048*E10,0),0) -> 0 | G10: =IFERROR(IF(VALUE(A10)>1997,D10*0.02,0),0) -> 2567.0752 | H10: =IFERROR(IF(VALUE($A10)>1996,(2026-$A10)*0.1048*G10,0),0) -> 6725.737 | I10: =IFERROR(IF(VALUE(A10)>1997,D10*0.01125,0),0) -> 1443.9798 | J10: =IFERROR(IF(VALUE($A10)>1996,(2026-$A10)*0.1048*I10,0),0) -> 3783.2271 | K10: =IFERROR(IF(VALUE(A10)<1997,0,IF(AND(VALUE(A10)>1997),D10*0.0315,0)),0) -> 4043.1434 | L10: =IFERROR(IF(VALUE($A10)>1996,(2026-$A10)*0.1048*K10,0),0) -> 10593.036 | N10: =IFERROR(IF(VALUE(A10)<1998,D10*0.05,0),0) -> 0 | O10: =IFERROR((2026-$A10)*0.1048*N10,0) -> 0 | P10: =IFERROR(IF(VALUE(A10)>1997,D10*0.05,0),0) -> 6417.688 | Q10: =IFERROR((2026-$A10)*0.1048*P10,0) -> 16814.343
A11: =IFERROR(YEAR(SalarioPromedio!B11),"") -> 2001 | B11: =SalarioPromedio!D11 -> 262.68 | C11: =IF(SalarioPromedio!B11="",0,SalarioPromedio!C11-SalarioPromedio!B11+1) -> 151 | D11: =IF(SalarioPromedio!B11="",0,C11*B11) -> 39664.68 | E11: =IFERROR(IF(VALUE(A11)<1998,D11*0.02,0),0) -> 0 | F11: =IFERROR(IF(VALUE($A11)>1996,(2026-$A11)*0.1048*E11,0),0) -> 0 | G11: =IFERROR(IF(VALUE(A11)>1997,D11*0.02,0),0) -> 793.2936 | H11: =IFERROR(IF(VALUE($A11)>1996,(2026-$A11)*0.1048*G11,0),0) -> 2078.4292 | I11: =IFERROR(IF(VALUE(A11)>1997,D11*0.01125,0),0) -> 446.22765 | J11: =IFERROR(IF(VALUE($A11)>1996,(2026-$A11)*0.1048*I11,0),0) -> 1169.1164 | K11: =IFERROR(IF(VALUE(A11)<1997,0,IF(AND(VALUE(A11)>1997),D11*0.0315,0)),0) -> 1249.4374 | L11: =IFERROR(IF(VALUE($A11)>1996,(2026-$A11)*0.1048*K11,0),0) -> 3273.526 | N11: =IFERROR(IF(VALUE(A11)<1998,D11*0.05,0),0) -> 0 | O11: =IFERROR((2026-$A11)*0.1048*N11,0) -> 0 | P11: =IFERROR(IF(VALUE(A11)>1997,D11*0.05,0),0) -> 1983.234 | Q11: =IFERROR((2026-$A11)*0.1048*P11,0) -> 5196.0731
A12: =IFERROR(YEAR(SalarioPromedio!B12),"") -> 2001 | B12: =SalarioPromedio!D12 -> 261.3 | C12: =IF(SalarioPromedio!B12="",0,SalarioPromedio!C12-SalarioPromedio!B12+1) -> 63 | D12: =IF(SalarioPromedio!B12="",0,C12*B12) -> 16461.9 | E12: =IFERROR(IF(VALUE(A12)<1998,D12*0.02,0),0) -> 0 | F12: =IFERROR(IF(VALUE($A12)>1996,(2026-$A12)*0.1048*E12,0),0) -> 0 | G12: =IFERROR(IF(VALUE(A12)>1997,D12*0.02,0),0) -> 329.238 | H12: =IFERROR(IF(VALUE($A12)>1996,(2026-$A12)*0.1048*G12,0),0) -> 862.60356 | I12: =IFERROR(IF(VALUE(A12)>1997,D12*0.01125,0),0) -> 185.19637 | J12: =IFERROR(IF(VALUE($A12)>1996,(2026-$A12)*0.1048*I12,0),0) -> 485.2145 | K12: =IFERROR(IF(VALUE(A12)<1997,0,IF(AND(VALUE(A12)>1997),D12*0.0315,0)),0) -> 518.54985 | L12: =IFERROR(IF(VALUE($A12)>1996,(2026-$A12)*0.1048*K12,0),0) -> 1358.6006 | N12: =IFERROR(IF(VALUE(A12)<1998,D12*0.05,0),0) -> 0 | O12: =IFERROR((2026-$A12)*0.1048*N12,0) -> 0 | P12: =IFERROR(IF(VALUE(A12)>1997,D12*0.05,0),0) -> 823.095 | Q12: =IFERROR((2026-$A12)*0.1048*P12,0) -> 2156.5089
A13: =IFERROR(YEAR(SalarioPromedio!B13),"") -> 2000 | B13: =SalarioPromedio!D13 -> 230 | C13: =IF(SalarioPromedio!B13="",0,SalarioPromedio!C13-SalarioPromedio!B13+1) -> 199 | D13: =IF(SalarioPromedio!B13="",0,C13*B13) -> 45770 | E13: =IFERROR(IF(VALUE(A13)<1998,D13*0.02,0),0) -> 0 | F13: =IFERROR(IF(VALUE($A13)>1996,(2026-$A13)*0.1048*E13,0),0) -> 0 | G13: =IFERROR(IF(VALUE(A13)>1997,D13*0.02,0),0) -> 915.4 | H13: =IFERROR(IF(VALUE($A13)>1996,(2026-$A13)*0.1048*G13,0),0) -> 2494.2819 | I13: =IFERROR(IF(VALUE(A13)>1997,D13*0.01125,0),0) -> 514.9125 | J13: =IFERROR(IF(VALUE($A13)>1996,(2026-$A13)*0.1048*I13,0),0) -> 1403.0336 | K13: =IFERROR(IF(VALUE(A13)<1997,0,IF(AND(VALUE(A13)>1997),D13*0.0315,0)),0) -> 1441.755 | L13: =IFERROR(IF(VALUE($A13)>1996,(2026-$A13)*0.1048*K13,0),0) -> 3928.494 | N13: =IFERROR(IF(VALUE(A13)<1998,D13*0.05,0),0) -> 0 | O13: =IFERROR((2026-$A13)*0.1048*N13,0) -> 0 | P13: =IFERROR(IF(VALUE(A13)>1997,D13*0.05,0),0) -> 2288.5 | Q13: =IFERROR((2026-$A13)*0.1048*P13,0) -> 6235.7048
A14: =IFERROR(YEAR(SalarioPromedio!B14),"") -> 1998 | B14: =SalarioPromedio!D14 -> 156.78 | C14: =IF(SalarioPromedio!B14="",0,SalarioPromedio!C14-SalarioPromedio!B14+1) -> 860 | D14: =IF(SalarioPromedio!B14="",0,C14*B14) -> 134830.8 | E14: =IFERROR(IF(VALUE(A14)<1998,D14*0.02,0),0) -> 0 | F14: =IFERROR(IF(VALUE($A14)>1996,(2026-$A14)*0.1048*E14,0),0) -> 0 | G14: =IFERROR(IF(VALUE(A14)>1997,D14*0.02,0),0) -> 2696.616 | H14: =IFERROR(IF(VALUE($A14)>1996,(2026-$A14)*0.1048*G14,0),0) -> 7912.95 | I14: =IFERROR(IF(VALUE(A14)>1997,D14*0.01125,0),0) -> 1516.8465 | J14: =IFERROR(IF(VALUE($A14)>1996,(2026-$A14)*0.1048*I14,0),0) -> 4451.0344 | K14: =IFERROR(IF(VALUE(A14)<1997,0,IF(AND(VALUE(A14)>1997),D14*0.0315,0)),0) -> 4247.1702 | L14: =IFERROR(IF(VALUE($A14)>1996,(2026-$A14)*0.1048*K14,0),0) -> 12462.896 | N14: =IFERROR(IF(VALUE(A14)<1998,D14*0.05,0),0) -> 0 | O14: =IFERROR((2026-$A14)*0.1048*N14,0) -> 0 | P14: =IFERROR(IF(VALUE(A14)>1997,D14*0.05,0),0) -> 6741.54 | Q14: =IFERROR((2026-$A14)*0.1048*P14,0) -> 19782.375
A15: =IFERROR(YEAR(SalarioPromedio!B15),"") -> 1996 | B15: =SalarioPromedio!D15 -> 104.52 | C15: =IF(SalarioPromedio!B15="",0,SalarioPromedio!C15-SalarioPromedio!B15+1) -> 487 | D15: =IF(SalarioPromedio!B15="",0,C15*B15) -> 50901.24 | E15: =IFERROR(IF(VALUE(A15)<1998,D15*0.02,0),0) -> 1018.0248 | F15: =IFERROR(IF(VALUE($A15)>1996,(2026-$A15)*0.1048*E15,0),0) -> 0 | G15: =IFERROR(IF(VALUE(A15)>1997,D15*0.02,0),0) -> 0 | H15: =IFERROR(IF(VALUE($A15)>1996,(2026-$A15)*0.1048*G15,0),0) -> 0 | I15: =IFERROR(IF(VALUE(A15)>1997,D15*0.01125,0),0) -> 0 | J15: =IFERROR(IF(VALUE($A15)>1996,(2026-$A15)*0.1048*I15,0),0) -> 0 | K15: =IFERROR(IF(VALUE(A15)<1997,0,IF(AND(VALUE(A15)>1997),D15*0.0315,0)),0) -> 0 | L15: =IFERROR(IF(VALUE($A15)>1996,(2026-$A15)*0.1048*K15,0),0) -> 0 | N15: =IFERROR(IF(VALUE(A15)<1998,D15*0.05,0),0) -> 2545.062 | O15: =IFERROR((2026-$A15)*0.1048*N15,0) -> 8001.6749 | P15: =IFERROR(IF(VALUE(A15)>1997,D15*0.05,0),0) -> 0 | Q15: =IFERROR((2026-$A15)*0.1048*P15,0) -> 0
A16: =IFERROR(YEAR(SalarioPromedio!B16),"") -> 1995 | B16: =SalarioPromedio!D16 -> 70 | C16: =IF(SalarioPromedio!B16="",0,SalarioPromedio!C16-SalarioPromedio!B16+1) -> 489 | D16: =IF(SalarioPromedio!B16="",0,C16*B16) -> 34230 | E16: =IFERROR(IF(VALUE(A16)<1998,D16*0.02,0),0) -> 684.6 | F16: =IFERROR(IF(VALUE($A16)>1996,(2026-$A16)*0.1048*E16,0),0) -> 0 | G16: =IFERROR(IF(VALUE(A16)>1997,D16*0.02,0),0) -> 0 | H16: =IFERROR(IF(VALUE($A16)>1996,(2026-$A16)*0.1048*G16,0),0) -> 0 | I16: =IFERROR(IF(VALUE(A16)>1997,D16*0.01125,0),0) -> 0 | J16: =IFERROR(IF(VALUE($A16)>1996,(2026-$A16)*0.1048*I16,0),0) -> 0 | K16: =IFERROR(IF(VALUE(A16)<1997,0,IF(AND(VALUE(A16)>1997),D16*0.0315,0)),0) -> 0 | L16: =IFERROR(IF(VALUE($A16)>1996,(2026-$A16)*0.1048*K16,0),0) -> 0 | N16: =IFERROR(IF(VALUE(A16)<1998,D16*0.05,0),0) -> 1711.5 | O16: =IFERROR((2026-$A16)*0.1048*N16,0) -> 5560.3212 | P16: =IFERROR(IF(VALUE(A16)>1997,D16*0.05,0),0) -> 0 | Q16: =IFERROR((2026-$A16)*0.1048*P16,0) -> 0
... A265: =IFERROR(YEAR(SalarioPromedio!B265),"") -> 1899 | B265: =SalarioPromedio!D265 | C265: =IF(SalarioPromedio!B265="",0,SalarioPromedio!C265-SalarioPromedio!B265+1) -> 0 | D265: =IF(SalarioPromedio!B265="",0,C265*B265) -> 0 | E265: =IFERROR(IF(VALUE(A265)<1998,D265*0.02,0),0) -> 0 | F265: =IFERROR(IF(VALUE($A265)>1996,(2026-$A265)*0.1048*E265,0),0) -> 0 | G265: =IFERROR(IF(VALUE(A265)>1997,D265*0.02,0),0) -> 0 | H265: =IFERROR(IF(VALUE($A265)>1996,(2026-$A265)*0.1048*G265,0),0) -> 0 | I265: =IFERROR(IF(VALUE(A265)>1997,D265*0.01125,0),0) -> 0 | J265: =IFERROR(IF(VALUE($A265)>1996,(2026-$A265)*0.1048*I265,0),0) -> 0 | K265: =IFERROR(IF(VALUE(A265)<1997,0,IF(AND(VALUE(A265)>1997),D265*0.0315,0)),0) -> 0 | L265: =IFERROR(IF(VALUE($A265)>1996,(2026-$A265)*0.1048*K265,0),0) -> 0 | N265: =IFERROR(IF(VALUE(A265)<1998,D265*0.05,0),0) -> 0 | O265: =IFERROR((2026-$A265)*0.1048*N265,0) -> 0 | P265: =IFERROR(IF(VALUE(A265)>1997,D265*0.05,0),0) -> 0 | Q265: =IFERROR((2026-$A265)*0.1048*P265,0) -> 0
A267: TOTALES | E267: =SUM(E5:E265) -> 1714.2414 | F267: =SUM(F5:F265) -> 0 | G267: =SUM(G5:G265) -> 19024.366 | H267: =SUM(H5:H265) -> 25825.359 | I267: =SUM(I5:I265) -> 10701.206 | J267: =SUM(J5:J265) -> 14526.765 | K267: =SUM(K5:K265) -> 29963.377 | L267: =SUM(L5:L265) -> 40674.941 | N267: =SUM(N5:N265) -> 4285.6035 | O267: =SUM(O5:O265) -> 13662.433 | P267: =SUM(P5:P265) -> 47560.916 | Q267: =SUM(Q5:Q265) -> 64563.398
E268: =SUM(E267:F267) -> 1714.2414 | G268: =SUM(G267:H267) -> 44849.726 | I268: =SUM(I267:J267) -> 25227.971 | K268: =SUM(K267:L267) -> 70638.318
E269: IMSS 92 | F269: =E268 -> 1714.2414 | G269: IMSS 97 | H269: =G268 -> 44849.726 | I269: RCV | J269: =I268+K268 -> 95866.288 | N269: VIVIENDA 92 | O269: =SUM(N267:O267) -> 17948.037 | P269: VIVIENDA 97 | Q269: =SUM(P267:Q267) -> 112124.31
